Workbook
Name age: global_cvd_burden!$E:$E
Name cases: global_cvd_burden!$I:$I
Name country: global_cvd_burden!$B:$B
Name deaths: global_cvd_burden!$J:$J
Name diabetes: global_cvd_burden!$N:$N
Name female_p: global_cvd_burden!$H:$H
Name health: global_cvd_burden!$Q:$Q
Name hypertension: global_cvd_burden!$O:$O
Name ID: global_cvd_burden!$A:$A
Name life: global_cvd_burden!$S:$S
Name male_p: global_cvd_burden!$G:$G
Name obesity: global_cvd_burden!$M:$M
Name physical: global_cvd_burden!$P:$P
Name population: global_cvd_burden!$F:$F
Name prevalence: global_cvd_burden!$K:$K
Name region: global_cvd_burden!$C:$C
Name risk: global_cvd_burden!$R:$R
Name Slicer_Year: #N/A
Name smoking: global_cvd_burden!$L:$L
Name year: global_cvd_burden!$D:$D

Sheet global_cvd_burden
A1: Country_ID | B1: Country | C1: Region | D1: Year | E1: Age_Group | F1: Population | G1: Male_Population | H1: Female_Population | I1: CVD_Cases | J1: CVD_Deaths | K1: CVD_Prevalence_% | L1: Smoking_Rate_% | M1: Obesity_Rate_% | N1: Diabetes_Rate_% | O1: Hypertension_Rate_% | P1: Physical_Inactivity_% | Q1: Health_Expenditure_USD | R1: Risk_Index | S1: Life_Expectancy
A2: 1 | B2: USA | C2: North America | D2: 2021 | E2: 18-39 | F2: 95164550 | G2: 49297001 | H2: 45867549 | I2: 5444171 | J2: 421555 | K2: 5.72 | L2: 16.24 | M2: 20.58 | N2: 13.28 | O2: 28.18 | P2: 28.74 | Q2: 816.93 | R2: 63 | S2: 77.3
A3: 1 | B3: USA | C3: North America | D3: 2021 | E3: 40-59 | F3: 167739055 | G3: 82727101 | H3: 85011954 | I3: 14999467 | J3: 677372 | K3: 8.94 | L3: 19.07 | M3: 13.35 | N3: 9.03 | O3: 24.07 | P3: 21.56 | Q3: 9129.19 | R3: 64 | S3: 66.4
A4: 1 | B4: USA | C4: North America | D4: 2021 | E4: 60+ | F4: 100150760 | G4: 52001227 | H4: 48149533 | I4: 9823072 | J4: 650675 | K4: 9.81 | L4: 20.82 | M4: 16.92 | N4: 6.61 | O4: 39.4 | P4: 27.9 | Q4: 1832.45 | R4: 61 | S4: 74.3
A5: 1 | B5: USA | C5: North America | D5: 2022 | E5: 18-39 | F5: 91664139 | G5: 46246403 | H5: 45417736 | I5: 8787372 | J5: 281017 | K5: 9.59 | L5: 20.57 | M5: 21.48 | N5: 5.62 | O5: 32.83 | P5: 36.32 | Q5: 7318.82 | R5: 74 | S5: 66
A6: 1 | B6: USA | C6: North America | D6: 2022 | E6: 40-59 | F6: 69582762 | G6: 34817810 | H6: 34764952 | I6: 5256591 | J6: 355616 | K6: 7.55 | L6: 12.96 | M6: 30.49 | N6: 11.83 | O6: 35.74 | P6: 19.79 | Q6: 9727.19 | R6: 77 | S6: 64.4
A7: 1 | B7: USA | C7: North America | D7: 2022 | E7: 60+ | F7: 96418285 | G7: 49579157 | H7: 46839128 | I7: 8973088 | J7: 662454 | K7: 9.31 | L7: 19.44 | M7: 16.85 | N7: 5.07 | O7: 32.91 | P7: 33 | Q7: 10109.05 | R7: 43 | S7: 66.5
A8: 1 | B8: USA | C8: North America | D8: 2023 | E8: 18-39 | F8: 94536589 | G8: 47795171 | H8: 46741418 | I8: 8532186 | J8: 667076 | K8: 9.03 | L8: 13.01 | M8: 22.06 | N8: 13.95 | O8: 28.45 | P8: 29.74 | Q8: 781.64 | R8: 49 | S8: 75.5
A9: 1 | B9: USA | C9: North America | D9: 2023 | E9: 40-59 | F9: 91157228 | G9: 46770313 | H9: 44386915 | I9: 8593940 | J9: 541570 | K9: 9.43 | L9: 14.91 | M9: 29.21 | N9: 7.12 | O9: 36.63 | P9: 16.57 | Q9: 9993.11 | R9: 81 | S9: 63.8
A10: 1 | B10: USA | C10: North America | D10: 2023 | E10: 60+ | F10: 29995044 | G10: 14777644 | H10: 15217400 | I10: 2536586 | J10: 98745 | K10: 8.46 | L10: 17.93 | M10: 10.15 | N10: 7.62 | O10: 28.42 | P10: 17.65 | Q10: 7781.34 | R10: 56 | S10: 68.7
A11: 1 | B11: USA | C11: North America | D11: 2024 | E11: 18-39 | F11: 5874572 | G11: 2973441 | H11: 2901131 | I11: 420392 | J11: 30842 | K11: 7.16 | L11: 22.64 | M11: 30.26 | N11: 8.42 | O11: 30.87 | P11: 19.91 | Q11: 11955.62 | R11: 72 | S11: 65.6
A12: 1 | B12: USA | C12: North America | D12: 2024 | E12: 40-59 | F12: 30204878 | G12: 14586769 | H12: 15618109 | I12: 1899589 | J12: 129469 | K12: 6.29 | L12: 23.96 | M12: 13.22 | N12: 8.76 | O12: 28.42 | P12: 31.62 | Q12: 5743.18 | R12: 51 | S12: 73.5
A13: 1 | B13: USA | C13: North America | D13: 2024 | E13: 60+ | F13: 91571160 | G13: 46615118 | H13: 44956042 | I13: 6249764 | J13: 327611 | K13: 6.83 | L13: 17.35 | M13: 12.74 | N13: 7.03 | O13: 25.68 | P13: 22.85 | Q13: 4100.05 | R13: 77 | S13: 73.3
... A1279: 71 | B1279: Rwanda | C1279: Africa | D1279: 2026 | E1279: 60+ | F1279: 150556902 | G1279: 73036237 | H1279: 77520665 | I1279: 13722091 | J1279: 879896 | K1279: 9.11 | L1279: 17.63 | M1279: 15.42 | N1279: 6.82 | O1279: 20.39 | P1279: 27.9 | Q1279: 10731.55 | R1279: 82 | S1279: 60.8

Sheet population
A3: Row Labels | B3: Sum of Population
A4: Algeria | B4: 201226927
A5: Angola | B5: 355207811
A6: Argentina | B6: 302709017
A7: Australia | B7: 273170517
A8: Austria | B8: 435139930
A9: Bangladesh | B9: 419625096
A10: Belgium | B10: 333570067
A11: Botswana | B11: 313783459
A12: Brazil | B12: 258944524
A13: Bulgaria | B13: 256475876
A14: Cameroon | B14: 397935382
A15: Canada | B15: 432460070
... A75: Grand Total | B75: 22281150067

Sheet M&F
A3: Row Labels | B3: Sum of Male_Population | D3: Row Labels | E3: Sum of Female_Population
A4: Africa | B4: 3212384326 | D4: Africa | E4: 3178675868
A5: Asia | B5: 2854571363 | D5: Asia | E5: 2846835864
A6: Europe | B6: 3379723479 | D6: Europe | E6: 3368903857
A7: North America | B7: 472386358 | D7: North America | E7: 492207453
A8: Oceania | B8: 349704158 | D8: Oceania | E8: 339398944
A9: South America | B9: 891536684 | D9: South America | E9: 894821713
A10: Grand Total | B10: 11160306368 | D10: Grand Total | E10: 11120843699

Sheet Age
A3: Row Labels | B3: Sum of Population
A4: 18-39 | B4: 7473277977
A5: 40-59 | B5: 6594037185
A6: 60+ | B6: 8213834905
A7: Grand Total | B7: 22281150067

Sheet Risk
A3: Row Labels | B3: Sum of Risk_index
A4: 18-39 | B4: 43
A5: 40-59 | B5: 40
A6: 60+ | B6: 58
A7: Grand Total | B7: 141

Sheet Smoking
A3: Row Labels | B3: Sum of Smoking_rate
A4: Algeria | B4: 54.87
A5: Angola | B5: 55.75
A6: Argentina | B6: 62.52
A7: Australia | B7: 54.77
A8: Austria | B8: 71.68
A9: Bangladesh | B9: 48.85
A10: Belgium | B10: 77.23
A11: Botswana | B11: 57.91
A12: Brazil | B12: 52.45
A13: Bulgaria | B13: 40.21
A14: Cameroon | B14: 55.6
A15: Canada | B15: 53.47
... A75: Grand Total | B75: 4165.1

Sheet Diabetes
A3: Row Labels | B3: Sum of Diabetes
A4: 18-39 | B4: 729.62
A5: 40-59 | B5: 704.74
A6: 60+ | B6: 697.1
A7: Grand Total | B7: 2131.46

Sheet Life
A3: Row Labels | B3: Sum of Life_Expectancy
A4: 18-39 | B4: 77.3
A5: 40-59 | B5: 66.4
A6: 60+ | B6: 74.3
A7: Grand Total | B7: 218

Sheet Health
A3: Row Labels | B3: Sum of Health_Expenditure
A4: Africa | B4: 1524.15
A5: Asia | B5: 9851.07
A6: Europe | B6: 7118.5
A7: North America | B7: 816.93
A8: Oceania | B8: 3199.32
A9: South America | B9: 3101.85
A10: Grand Total | B10: 25611.82

Sheet CVD
A3: Row Labels | B3: Sum of CVD_Cases
A4: 2021 | B4: 5444171
A5: 2022 | B5: 8787372
A6: 2023 | B6: 8532186
A7: 2024 | B7: 420392
A8: 2025 | B8: 2546895
A9: 2026 | B9: 10403663
A10: Grand Total | B10: 36134679

Sheet YEAR
A3: Row Labels
A4: 2021
A5: 2022
A6: 2023
A7: 2024
A8: 2025
A9: 2026
A10: Grand Total

Sheet TABLE
E1: Selection of year | F1: 2024
A3: {=_xlfn.UNIQUE(country,FALSE)} -> Country | B3: Population | D3: {=_xlfn.UNIQUE(year)} -> Year | F3: {=_xlfn.UNIQUE(region)} -> Region | G3: Male_Population | H3: Female_Population | J3: {=_xlfn.UNIQUE(age)} -> Age_Group | K3: Population | M3: {=_xlfn.UNIQUE(age)} -> Age_Group | N3: Risk_index
A4: USA | B4: =SUMIFS(population,country,TABLE!A4,year,TABLE!$F$1) -> 127650610 | D4: 2021 | F4: North America | G4: =SUMIFS(male_p,region,F4,year,$F$1) -> 472386358 | H4: =SUMIFS(female_p,region,F4,year,$F$1) -> 492207453 | J4: 18-39 | K4: =SUMIFS(population,age,J4,year,$F$1) -> 7473277977 | M4: 18-39 | N4: =LOOKUP(M4,age,risk) -> 43
A5: Canada | B5: =SUMIFS(population,country,TABLE!A5,year,TABLE!$F$1) -> 432460070 | D5: 2022 | F5: South America | G5: =SUMIFS(male_p,region,F5,year,$F$1) -> 891536684 | H5: =SUMIFS(female_p,region,F5,year,$F$1) -> 894821713 | J5: 40-59 | K5: =SUMIFS(population,age,J5,year,$F$1) -> 6594037185 | M5: 40-59 | N5: =LOOKUP(M5,age,risk) -> 40
A6: Mexico | B6: =SUMIFS(population,country,TABLE!A6,year,TABLE!$F$1) -> 404483131 | D6: 2023 | F6: Europe | G6: =SUMIFS(male_p,region,F6,year,$F$1) -> 3379723479 | H6: =SUMIFS(female_p,region,F6,year,$F$1) -> 3368903857 | J6: 60+ | K6: =SUMIFS(population,age,J6,year,$F$1) -> 8213834905 | M6: 60+ | N6: =LOOKUP(M6,age,risk) -> 58
A7: Brazil | B7: =SUMIFS(population,country,TABLE!A7,year,TABLE!$F$1) -> 258944524 | D7: 2024 | F7: Asia | G7: =SUMIFS(male_p,region,F7,year,$F$1) -> 2854571363 | H7: =SUMIFS(female_p,region,F7,year,$F$1) -> 2846835864 | J7: 0 | M7: 0
A8: Argentina | B8: =SUMIFS(population,country,TABLE!A8,year,TABLE!$F$1) -> 302709017 | D8: 2025 | F8: Oceania | G8: =SUMIFS(male_p,region,F8,year,$F$1) -> 349704158 | H8: =SUMIFS(female_p,region,F8,year,$F$1) -> 339398944
A9: Chile | B9: =SUMIFS(population,country,TABLE!A9,year,TABLE!$F$1) -> 525629365 | D9: 2026 | F9: Africa | G9: =SUMIFS(male_p,region,F9,year,$F$1) -> 3212384326 | H9: =SUMIFS(female_p,region,F9,year,$F$1) -> 3178675868
A10: Peru | B10: =SUMIFS(population,country,TABLE!A10,year,TABLE!$F$1) -> 335077150 | D10: 0 | F10: 0
A11: Colombia | B11: =SUMIFS(population,country,TABLE!A11,year,TABLE!$F$1) -> 363998341
A12: UK | B12: =SUMIFS(population,country,TABLE!A12,year,TABLE!$F$1) -> 296699949 | D12: {=_xlfn.UNIQUE(year)} -> Year | E12: Death | G12: {=_xlfn.UNIQUE(country)} -> Country | H12: Smoking_rate | J12: {=_xlfn.UNIQUE(age)} -> Age_Group | K12: Diabetes | M12: {=_xlfn.UNIQUE(age)} -> Age_Group | N12: Life_Expectancy
A13: Germany | B13: =SUMIFS(population,country,TABLE!A13,year,TABLE!$F$1) -> 157955383 | D13: 2021 | E13: =SUMIFS(deaths,year,D13,year,$F$1) -> 0 | G13: USA | H13: =SUMIFS(smoking,country,G13,year,$F$1) -> 63.95 | J13: 18-39 | K13: =SUMIFS(diabetes,age,J13,year,$F$1) -> 729.62 | M13: 18-39 | N13: =INDEX(life,MATCH(M13,age,0)) -> 77.3
A14: France | B14: =SUMIFS(population,country,TABLE!A14,year,TABLE!$F$1) -> 247967993 | D14: 2022 | E14: =SUMIFS(deaths,year,D14,year,$F$1) -> 0 | G14: Canada | H14: =SUMIFS(smoking,country,G14,year,$F$1) -> 53.47 | J14: 40-59 | K14: =SUMIFS(diabetes,age,J14,year,$F$1) -> 704.74 | M14: 40-59 | N14: =INDEX(life,MATCH(M14,age,0)) -> 66.4
A15: Italy | B15: =SUMIFS(population,country,TABLE!A15,year,TABLE!$F$1) -> 253472098 | D15: 2023 | E15: =SUMIFS(deaths,year,D15,year,$F$1) -> 0 | G15: Mexico | H15: =SUMIFS(smoking,country,G15,year,$F$1) -> 47.73 | J15: 60+ | K15: =SUMIFS(diabetes,age,J15,year,$F$1) -> 697.1 | M15: 60+ | N15: =INDEX(life,MATCH(M15,age,0)) -> 74.3
A16: Spain | B16: =SUMIFS(population,country,TABLE!A16,year,TABLE!$F$1) -> 165425123 | D16: 2024 | E16: =SUMIFS(deaths,year,D16,year,$F$1) -> 91546740 | G16: Brazil | H16: =SUMIFS(smoking,country,G16,year,$F$1) -> 52.45 | J16: 0 | M16: 0
A17: Netherlands | B17: =SUMIFS(population,country,TABLE!A17,year,TABLE!$F$1) -> 409776057 | D17: 2025 | E17: =SUMIFS(deaths,year,D17,year,$F$1) -> 0 | G17: Argentina | H17: =SUMIFS(smoking,country,G17,year,$F$1) -> 62.52
A18: Sweden | B18: =SUMIFS(population,country,TABLE!A18,year,TABLE!$F$1) -> 393159200 | D18: 2026 | E18: =SUMIFS(deaths,year,D18,year,$F$1) -> 0 | G18: Chile | H18: =SUMIFS(smoking,country,G18,year,$F$1) -> 52.93 | J18: {=_xlfn.UNIQUE(region)} -> Region | K18: Health_Expenditure | M18: {=_xlfn.UNIQUE(year)} -> Year | N18: CVD_Cases
A19: Norway | B19: =SUMIFS(population,country,TABLE!A19,year,TABLE!$F$1) -> 339441045 | D19: 0 | G19: Peru | H19: =SUMIFS(smoking,country,G19,year,$F$1) -> 82.76 | J19: North America | K19: =INDEX(health,MATCH(J19,region,0)) -> 816.93 | M19: 2021 | N19: =_xlfn.XLOOKUP(M19,year,cases,"Not found") -> 5444171
A20: Belgium | B20: =SUMIFS(population,country,TABLE!A20,year,TABLE!$F$1) -> 333570067 | G20: Colombia | H20: =SUMIFS(smoking,country,G20,year,$F$1) -> 62.38 | J20: South America | K20: =INDEX(health,MATCH(J20,region,0)) -> 3101.85 | M20: 2022 | N20: =_xlfn.XLOOKUP(M20,year,cases,"Not found") -> 8787372
A21: Austria | B21: =SUMIFS(population,country,TABLE!A21,year,TABLE!$F$1) -> 435139930 | G21: UK | H21: =SUMIFS(smoking,country,G21,year,$F$1) -> 60.61 | J21: Europe | K21: =INDEX(health,MATCH(J21,region,0)) -> 7118.5 | M21: 2023 | N21: =_xlfn.XLOOKUP(M21,year,cases,"Not found") -> 8532186
A22: Switzerland | B22: =SUMIFS(population,country,TABLE!A22,year,TABLE!$F$1) -> 361320978 | G22: Germany | H22: =SUMIFS(smoking,country,G22,year,$F$1) -> 55.3 | J22: Asia | K22: =INDEX(health,MATCH(J22,region,0)) -> 9851.07 | M22: 2024 | N22: =_xlfn.XLOOKUP(M22,year,cases,"Not found") -> 420392
A23: Denmark | B23: =SUMIFS(population,country,TABLE!A23,year,TABLE!$F$1) -> 334983307 | G23: France | H23: =SUMIFS(smoking,country,G23,year,$F$1) -> 72.12 | J23: Oceania | K23: =INDEX(health,MATCH(J23,region,0)) -> 3199.32 | M23: 2025 | N23: =_xlfn.XLOOKUP(M23,year,cases,"Not found") -> 2546895
A24: Finland | B24: =SUMIFS(population,country,TABLE!A24,year,TABLE!$F$1) -> 415691408 | G24: Italy | H24: =SUMIFS(smoking,country,G24,year,$F$1) -> 65.08 | J24: Africa | K24: =INDEX(health,MATCH(J24,region,0)) -> 1524.15 | M24: 2026 | N24: =_xlfn.XLOOKUP(M24,year,cases,"Not found") -> 10403663
A25: Poland | B25: =SUMIFS(population,country,TABLE!A25,year,TABLE!$F$1) -> 136404477 | G25: Spain | H25: =SUMIFS(smoking,country,G25,year,$F$1) -> 73.99 | J25: 0 | M25: 0
A26: Portugal | B26: =SUMIFS(population,country,TABLE!A26,year,TABLE!$F$1) -> 360573339 | G26: Netherlands | H26: =SUMIFS(smoking,country,G26,year,$F$1) -> 79.77
A27: Greece | B27: =SUMIFS(population,country,TABLE!A27,year,TABLE!$F$1) -> 459277723 | G27: Sweden | H27: =SUMIFS(smoking,country,G27,year,$F$1) -> 58.3
A28: Czech Republic | B28: =SUMIFS(population,country,TABLE!A28,year,TABLE!$F$1) -> 215268629 | G28: Norway | H28: =SUMIFS(smoking,country,G28,year,$F$1) -> 51.75
A29: Hungary | B29: =SUMIFS(population,country,TABLE!A29,year,TABLE!$F$1) -> 272542057 | G29: Belgium | H29: =SUMIFS(smoking,country,G29,year,$F$1) -> 77.23
A30: Romania | B30: =SUMIFS(population,country,TABLE!A30,year,TABLE!$F$1) -> 434793610 | G30: Austria | H30: =SUMIFS(smoking,country,G30,year,$F$1) -> 71.68
A31: Bulgaria | B31: =SUMIFS(population,country,TABLE!A31,year,TABLE!$F$1) -> 256475876 | G31: Switzerland | H31: =SUMIFS(smoking,country,G31,year,$F$1) -> 49.72
A32: Russia | B32: =SUMIFS(population,country,TABLE!A32,year,TABLE!$F$1) -> 259553646 | G32: Denmark | H32: =SUMIFS(smoking,country,G32,year,$F$1) -> 36.63
A33: Ukraine | B33: =SUMIFS(population,country,TABLE!A33,year,TABLE!$F$1) -> 209135441 | G33: Finland | H33: =SUMIFS(smoking,country,G33,year,$F$1) -> 70.9
A34: India | B34: =SUMIFS(population,country,TABLE!A34,year,TABLE!$F$1) -> 326369701 | G34: Poland | H34: =SUMIFS(smoking,country,G34,year,$F$1) -> 61.36
A35: China | B35: =SUMIFS(population,country,TABLE!A35,year,TABLE!$F$1) -> 279879083 | G35: Portugal | H35: =SUMIFS(smoking,country,G35,year,$F$1) -> 52.99
A36: Japan | B36: =SUMIFS(population,country,TABLE!A36,year,TABLE!$F$1) -> 374631626 | G36: Greece | H36: =SUMIFS(smoking,country,G36,year,$F$1) -> 65.72
A37: South Korea | B37: =SUMIFS(population,country,TABLE!A37,year,TABLE!$F$1) -> 369499204 | G37: Czech Republic | H37: =SUMIFS(smoking,country,G37,year,$F$1) -> 55.35
... A74: Rwanda | B74: =SUMIFS(population,country,TABLE!A74,year,TABLE!$F$1) -> 403835455 | G74: Sudan | H74: =SUMIFS(smoking,country,G74,year,$F$1) -> 47.63
A75: 0 | G75: Uganda | H75: =SUMIFS(smoking,country,G75,year,$F$1) -> 51.1
G76: Zambia | H76: =SUMIFS(smoking,country,G76,year,$F$1) -> 53.78
G77: Zimbabwe | H77: =SUMIFS(smoking,country,G77,year,$F$1) -> 51.98
...

Sheet Dashboard
